Workbook
Name clientes: [1]CLIENTES!$A$1:$A$3
Name clientes: [1]CLIENTES!$A$1:$A$3
Name clientes: [2]CLIENTES!$A$1:$A$3
Name clientes: [3]CLIENTES!$A$1:$A$3
Name codigos: 'DETALLE PRODUCTOSxPrecio'!$A$8:$A$99
Name codigos: 'DETALLE PRODUCTOSxPrecio (2)'!$A$8:$A$98
Name codigos: #REF!
Name datos: 'DETALLE PRODUCTOSxPrecio'!$A$7:$AJ$99
Name datos: 'DETALLE PRODUCTOSxPrecio (2)'!$A$7:$AE$98
Name datos: #REF!

Sheet DETALLE PRODUCTOSxPrecio (2)
J1: VALIDAR PRECIO
A2: PRECIOS ACTUALIZADOS ABRIL 2025 | J2: FALTA PRECIO PROD
J3: FALTA PRECIO PROD Y VALIDAR RECETA
J4: FALTA RECETA | P4: #1 ELAINE | T4: #2 CALICHE | X4: #3 VICTOR
D5: SAI OPEN | P5: INF PARA SAI OPEN | T5: INF PARA SAI OPEN | X5: INF PARA SAI OPEN | AC5: VALORES ACTUALES
AC6: A-0001 | AD6: B-0001 | AE6: C-0001
A7: CODIGO | B7: PRODUCTO | C7: PRESENTACION | D7: LINEA | E7: GRUPO | F7: SUB GRUPO | G7: MARCA | H7: CAMARAS DE COMERCIO DE DISTRIBUIDORES | I7: LUGAR DE ALMACENAMIENTO | J7: PRECIO DE PRODUCCIÓN POR UND | K7: TOTAL GASTOS VARIOS | L7: COSTO TOTAL UNIDAD | M7: COSTO UTILIDAD | N7: UTILIDAD | O7: PRECIO VENTA POR RECETA | P7: PRECIO DE VENTA 1 | Q7: % GANANCIA | R7: VALOR UTILIDAD | S7: DIF EN PRECIO | T7: PRECIO DE VENTA2 | U7: % GANANCIA2 | V7: VALOR UTILIDAD2 | W7: DIF EN PRECIO5 | X7: PRECIO DE VENTA 3 | Y7: % GANANCIA3 | Z7: VALOR UTILIDAD22 | AA7: DIF EN PRECIO55 | AB7: OBSERVACIONES | AC7: ELAINE GARZON | AD7: CALICHE-MANZ | AE7: VICTOR-CALI | AF7: VARIOS | AG7: OBSERVACION | AH7: ESTADO DE RECETAS
A8: 7T01 | B8: 7 TOROS | C8: 500 ML-Jarabe | D8: HOMEOPATICOS | E8: JARABES | F8: 500 ML | G8: NATURAL PALAGAR | I8: MARIA-IMPERIO NATURAL | J8: ='RECETAS JARABES'!G68 -> 2046.4421 | K8: ='Gtos Varios'!$B$22 -> 3070.5429 | L8: =+LISTPROD3[[#This Row],[PRECIO DE PRODUCCIÓN POR UND]]+LISTPROD3[[#This Row],[TOTAL GASTOS VARIOS]] -> 5116.985 | M8: ='RECETAS JARABES'!G73 -> 3088.4609 | N8: ='RECETAS JARABES'!H73 -> 0.54 | O8: ='RECETAS JARABES'!G74 -> 8807.8331 | P8: 8000 | Q8: =(LISTPROD3[[#This Row],[PRECIO DE VENTA 1]]-LISTPROD3[[#This Row],[COSTO TOTAL UNIDAD]])/LISTPROD3[[#This Row],[COSTO TOTAL UNIDAD]] -> 0.56342066 | R8: =LISTPROD3[[#This Row],[% GANANCIA]]*LISTPROD3[[#This Row],[COSTO TOTAL UNIDAD]] -> 2883.015 | S8: =+LISTPROD3[[#This Row],[PRECIO DE VENTA 1]]-LISTPROD3[[#This Row],[PRECIO VENTA POR RECETA]] -> -807.83305 | X8: 0 | AC8: 8000 | AD8: 0 | AE8: 0 | AF8: 0 | AH8: OK
A9: AM01 | B9: ALICITRIM LITRO | C9: 1000 ML-Jarabe | D9: HOMEOPATICOS | E9: JARABES | F9: LITRO 1000 ML | G9: CUBANO | I9: ANGIE-LHC | J9: ='RECETAS JARABES'!G98 -> 2074.0653 | K9: ='Gtos Varios'!$B$22 -> 3070.5429 | L9: =+LISTPROD3[[#This Row],[PRECIO DE PRODUCCIÓN POR UND]]+LISTPROD3[[#This Row],[TOTAL GASTOS VARIOS]] -> 5144.6082 | M9: ='RECETAS JARABES'!G103 -> 3390.7272 | N9: ='RECETAS JARABES'!$H$103 -> 0.59 | O9: ='RECETAS JARABES'!$G$104 -> 9137.7226 | P9: 7500 | Q9: =(LISTPROD3[[#This Row],[PRECIO DE VENTA 1]]-LISTPROD3[[#This Row],[COSTO TOTAL UNIDAD]])/LISTPROD3[[#This Row],[COSTO TOTAL UNIDAD]] -> 0.45783697 | R9: =LISTPROD3[[#This Row],[% GANANCIA]]*LISTPROD3[[#This Row],[COSTO TOTAL UNIDAD]] -> 2355.3918 | S9: =+LISTPROD3[[#This Row],[PRECIO DE VENTA 1]]-LISTPROD3[[#This Row],[PRECIO VENTA POR RECETA]] -> -1637.7226 | X9: 0 | AC9: 7500 | AD9: 0 | AE9: 0 | AF9: 0 | AH9: PREGUNTAR A LUIS POR PRECIOS Y FORMULA | AL9: CLIENTES
A10: AN01 | B10: ARBRON | C10: 500 ML-Jarabe | D10: HOMEOPATICOS | E10: JARABES | F10: 500 ML | G10: NATURAL PALAGAR | I10: MARIA-IMPERIO NATURAL | J10: ='RECETAS JARABES'!G132 -> 1088.0283 | K10: ='Gtos Varios'!$B$22 -> 3070.5429 | L10: =+LISTPROD3[[#This Row],[PRECIO DE PRODUCCIÓN POR UND]]+LISTPROD3[[#This Row],[TOTAL GASTOS VARIOS]] -> 4158.5711 | M10: ='RECETAS JARABES'!G137 -> 3475.4995 | N10: ='RECETAS JARABES'!$H$137 -> 0.73 | O10: ='RECETAS JARABES'!$G$138 -> 8236.4578 | P10: 7000 | Q10: =(LISTPROD3[[#This Row],[PRECIO DE VENTA 1]]-LISTPROD3[[#This Row],[COSTO TOTAL UNIDAD]])/LISTPROD3[[#This Row],[COSTO TOTAL UNIDAD]] -> 0.68327047 | R10: =LISTPROD3[[#This Row],[% GANANCIA]]*LISTPROD3[[#This Row],[COSTO TOTAL UNIDAD]] -> 2841.4289 | S10: =+LISTPROD3[[#This Row],[PRECIO DE VENTA 1]]-LISTPROD3[[#This Row],[PRECIO VENTA POR RECETA]] -> -1236.4578 | X10: 0 | AC10: 7000 | AD10: 0 | AE10: 0 | AF10: 0 | AH10: OK | AL10: PRECIO 1
A11: AV01 | B11: ARTERIO VENOSO | C11: 500 ML-Jarabe | D11: HOMEOPATICOS | E11: JARABES | F11: 500 ML | G11: PHARMA | I11: LUIS-FARMACIA NATIVA | J11: ='RECETAS JARABES'!G167 -> 2134.0639 | K11: ='Gtos Varios'!$B$22 -> 3070.5429 | L11: =+LISTPROD3[[#This Row],[PRECIO DE PRODUCCIÓN POR UND]]+LISTPROD3[[#This Row],[TOTAL GASTOS VARIOS]] -> 5204.6067 | M11: ='RECETAS JARABES'!G172 -> 3368.0565 | N11: ='RECETAS JARABES'!$H$172 -> 0.58 | O11: ='RECETAS JARABES'!$G$173 -> 9175.0503 | P11: 6000 | Q11: =(LISTPROD3[[#This Row],[PRECIO DE VENTA 1]]-LISTPROD3[[#This Row],[COSTO TOTAL UNIDAD]])/LISTPROD3[[#This Row],[COSTO TOTAL UNIDAD]] -> 0.15282485 | R11: =LISTPROD3[[#This Row],[% GANANCIA]]*LISTPROD3[[#This Row],[COSTO TOTAL UNIDAD]] -> 795.39326 | S11: =+LISTPROD3[[#This Row],[PRECIO DE VENTA 1]]-LISTPROD3[[#This Row],[PRECIO VENTA POR RECETA]] -> -3175.0503 | T11: 5000 | U11: =(LISTPROD3[[#This Row],[PRECIO DE VENTA2]]-LISTPROD3[[#This Row],[COSTO TOTAL UNIDAD]])/LISTPROD3[[#This Row],[COSTO TOTAL UNIDAD]] -> -0.039312622 | V11: =+LISTPROD3[[#This Row],[% GANANCIA2]]*LISTPROD3[[#This Row],[COSTO TOTAL UNIDAD]] -> -204.60674 | W11: =LISTPROD3[[#This Row],[PRECIO DE VENTA2]]-LISTPROD3[[#This Row],[PRECIO VENTA POR RECETA]] -> -4175.0503 | X11: 5000 | Y11: =(LISTPROD3[[#This Row],[PRECIO DE VENTA 3]]-LISTPROD3[[#This Row],[COSTO TOTAL UNIDAD]])/LISTPROD3[[#This Row],[COSTO TOTAL UNIDAD]] -> -0.039312622 | Z11: =LISTPROD3[[#This Row],[% GANANCIA3]]*LISTPROD3[[#This Row],[COSTO TOTAL UNIDAD]] -> -204.60674 | AC11: 6000 | AD11: 5000 | AE11: 5000 | AF11: 5000 | AH11: OK | AL11: PRECIO 2-MANZ
A12: A01 | B12: ARTRIN | C12: PASTILLAS 30 | D12: HOMEOPATICOS | E12: PASTILLAS | F12: PASTILLAS DE 30 UND | I12: LUIS-FARMACIA NATIVA | J12: ='RECETAS PASTILLAS'!G16 -> 2450 | K12: ='Gtos Varios'!$B$22 -> 3070.5429 | L12: =+LISTPROD3[[#This Row],[TOTAL GASTOS VARIOS]]+LISTPROD3[[#This Row],[PRECIO DE PRODUCCIÓN POR UND]] -> 5520.5429 | M12: ='RECETAS PASTILLAS'!G21 -> 3367.6115 | N12: ='RECETAS PASTILLAS'!H21 -> 0.55 | O12: ='RECETAS PASTILLAS'!G22 -> 9490.5415 | P12: 3200 | Q12: =(LISTPROD3[[#This Row],[PRECIO DE VENTA 1]]-LISTPROD3[[#This Row],[COSTO TOTAL UNIDAD]])/LISTPROD3[[#This Row],[COSTO TOTAL UNIDAD]] -> -0.42034686 | R12: =LISTPROD3[[#This Row],[% GANANCIA]]*LISTPROD3[[#This Row],[COSTO TOTAL UNIDAD]] -> -2320.5429 | T12: 3200 | U12: =(LISTPROD3[[#This Row],[PRECIO DE VENTA2]]-LISTPROD3[[#This Row],[COSTO TOTAL UNIDAD]])/LISTPROD3[[#This Row],[COSTO TOTAL UNIDAD]] -> -0.42034686 | V12: =LISTPROD3[[#This Row],[PRECIO DE VENTA2]]*LISTPROD3[[#This Row],[% GANANCIA2]] -> -1345.11 | X12: 3200 | Y12: =(LISTPROD3[[#This Row],[PRECIO DE VENTA 3]]-LISTPROD3[[#This Row],[COSTO TOTAL UNIDAD]])/LISTPROD3[[#This Row],[COSTO TOTAL UNIDAD]] -> -0.42034686 | Z12: =+LISTPROD3[[#This Row],[PRECIO DE VENTA 3]]*LISTPROD3[[#This Row],[% GANANCIA3]] -> -1345.11 | AB12: Se toma solo el costo de produccion no margen de utilidad | AC12: 3200 | AD12: 3200 | AE12: 3200 | AF12: 3200 | AH12: OK-26/3/2025 | AL12: PRECIO 3-Victor
A13: BP01 | B13: BIL PRO | C13: 500 ML-Jarabe | D13: HOMEOPATICOS | E13: JARABES | F13: 500 ML | G13: NATURAL PALAGAR | I13: MARIA-IMPERIO NATURAL | J13: ='RECETAS JARABES'!G200 -> 949.4736 | K13: ='Gtos Varios'!$B$22 -> 3070.5429 | L13: =+LISTPROD3[[#This Row],[PRECIO DE PRODUCCIÓN POR UND]]+LISTPROD3[[#This Row],[TOTAL GASTOS VARIOS]] -> 4020.0165 | M13: ='RECETAS JARABES'!G205 -> 3374.3546 | N13: ='RECETAS JARABES'!H205 -> 0.73 | O13: ='RECETAS JARABES'!G206 -> 7996.7582 | P13: 7000 | Q13: =(LISTPROD3[[#This Row],[PRECIO DE VENTA 1]]-LISTPROD3[[#This Row],[COSTO TOTAL UNIDAD]])/LISTPROD3[[#This Row],[COSTO TOTAL UNIDAD]] -> 0.7412864 | R13: =LISTPROD3[[#This Row],[% GANANCIA]]*LISTPROD3[[#This Row],[COSTO TOTAL UNIDAD]] -> 2979.9835 | S13: =+LISTPROD3[[#This Row],[PRECIO DE VENTA 1]]-LISTPROD3[[#This Row],[PRECIO VENTA POR RECETA]] -> -996.75823 | AC13: 7000 | AD13: 0 | AE13: 0 | AF13: 0 | AH13: OK
A14: B01 | B14: BIO 44 | C14: 500 ML-Jarabe | D14: HOMEOPATICOS | E14: JARABES | F14: 500 ML | G14: PHARMA | I14: LUIS-FARMACIA NATIVA | J14: ='RECETAS JARABES'!G232 -> 2388.8636 | K14: ='Gtos Varios'!$B$22 -> 3070.5429 | L14: =+LISTPROD3[[#This Row],[PRECIO DE PRODUCCIÓN POR UND]]+LISTPROD3[[#This Row],[TOTAL GASTOS VARIOS]] -> 5459.4064 | M14: ='RECETAS JARABES'!G237 -> 3333.9865 | N14: ='RECETAS JARABES'!H237 -> 0.55 | O14: ='RECETAS JARABES'!G238 -> 9395.78 | P14: 6000 | Q14: =(LISTPROD3[[#This Row],[PRECIO DE VENTA 1]]-LISTPROD3[[#This Row],[COSTO TOTAL UNIDAD]])/LISTPROD3[[#This Row],[COSTO TOTAL UNIDAD]] -> 0.099020578 | R14: =LISTPROD3[[#This Row],[% GANANCIA]]*LISTPROD3[[#This Row],[COSTO TOTAL UNIDAD]] -> 540.59358 | S14: =+LISTPROD3[[#This Row],[PRECIO DE VENTA 1]]-LISTPROD3[[#This Row],[PRECIO VENTA POR RECETA]] -> -3395.78 | T14: 5000 | U14: =(LISTPROD3[[#This Row],[PRECIO DE VENTA2]]-LISTPROD3[[#This Row],[COSTO TOTAL UNIDAD]])/LISTPROD3[[#This Row],[COSTO TOTAL UNIDAD]] -> -0.084149518 | V14: =+LISTPROD3[[#This Row],[% GANANCIA2]]*LISTPROD3[[#This Row],[COSTO TOTAL UNIDAD]] -> -459.40642 | W14: =LISTPROD3[[#This Row],[PRECIO DE VENTA2]]-LISTPROD3[[#This Row],[PRECIO VENTA POR RECETA]] -> -4395.78 | X14: 5000 | Y14: =(LISTPROD3[[#This Row],[PRECIO DE VENTA 3]]-LISTPROD3[[#This Row],[COSTO TOTAL UNIDAD]])/LISTPROD3[[#This Row],[COSTO TOTAL UNIDAD]] -> -0.084149518 | Z14: =LISTPROD3[[#This Row],[% GANANCIA3]]*LISTPROD3[[#This Row],[COSTO TOTAL UNIDAD]] -> -459.40642 | AC14: 6000 | AD14: 5000 | AE14: 5000 | AF14: 5000 | AH14: FALTA
A15: BO01 | B15: BOTANPROS | C15: 500 ML-Jarabe | D15: HOMEOPATICOS | E15: JARABES | F15: 500 ML | G15: N/A | I15: LUIS-FARMACIA NATIVA | J15: ='RECETAS JARABES'!G264 -> 984.66726 | K15: ='Gtos Varios'!$B$22 -> 3070.5429 | L15: =+LISTPROD3[[#This Row],[PRECIO DE PRODUCCIÓN POR UND]]+LISTPROD3[[#This Row],[TOTAL GASTOS VARIOS]] -> 4055.2101 | M15: ='RECETAS JARABES'!G269 -> 3353.47 | N15: ='RECETAS JARABES'!H269 -> 0.72 | O15: ='RECETAS JARABES'!G270 -> 8011.0673 | P15: 7000 | Q15: =(LISTPROD3[[#This Row],[PRECIO DE VENTA 1]]-LISTPROD3[[#This Row],[COSTO TOTAL UNIDAD]])/LISTPROD3[[#This Row],[COSTO TOTAL UNIDAD]] -> 0.72617443 | R15: =LISTPROD3[[#This Row],[% GANANCIA]]*LISTPROD3[[#This Row],[COSTO TOTAL UNIDAD]] -> 2944.7899 | S15: =+LISTPROD3[[#This Row],[PRECIO DE VENTA 1]]-LISTPROD3[[#This Row],[PRECIO VENTA POR RECETA]] -> -1011.0673 | T15: 5000 | U15: =(LISTPROD3[[#This Row],[PRECIO DE VENTA2]]-LISTPROD3[[#This Row],[COSTO TOTAL UNIDAD]])/LISTPROD3[[#This Row],[COSTO TOTAL UNIDAD]] -> 0.23298173 | V15: =+LISTPROD3[[#This Row],[% GANANCIA2]]*LISTPROD3[[#This Row],[COSTO TOTAL UNIDAD]] -> 944.78989 | W15: =LISTPROD3[[#This Row],[PRECIO DE VENTA2]]-LISTPROD3[[#This Row],[PRECIO VENTA POR RECETA]] -> -3011.0673 | X15: 5000 | Y15: =(LISTPROD3[[#This Row],[PRECIO DE VENTA 3]]-LISTPROD3[[#This Row],[COSTO TOTAL UNIDAD]])/LISTPROD3[[#This Row],[COSTO TOTAL UNIDAD]] -> 0.23298173 | Z15: =LISTPROD3[[#This Row],[% GANANCIA3]]*LISTPROD3[[#This Row],[COSTO TOTAL UNIDAD]] -> 944.78989 | AC15: 7000 | AD15: 5000 | AE15: 5000 | AF15: 5000 | AH15: OK
A16: CO01 | B16: CALCUBANO LITRO | C16: 1000 ML-Jarabe | D16: HOMEOPATICOS | E16: JARABES | F16: LITRO 1000 ML | G16: CUBANO | I16: ANGIE-LHC | J16: ='RECETAS JARABES'!G295 -> 2745.6159 | K16: ='Gtos Varios'!$B$22 -> 3070.5429 | L16: =+LISTPROD3[[#This Row],[PRECIO DE PRODUCCIÓN POR UND]]+LISTPROD3[[#This Row],[TOTAL GASTOS VARIOS]] -> 5816.1587 | M16: ='RECETAS JARABES'!$G$300 -> 3337.6439 | N16: ='RECETAS JARABES'!H300 -> 0.52 | O16: ='RECETAS JARABES'!G301 -> 9756.1897 | P16: 7500 | Q16: =(LISTPROD3[[#This Row],[PRECIO DE VENTA 1]]-LISTPROD3[[#This Row],[COSTO TOTAL UNIDAD]])/LISTPROD3[[#This Row],[COSTO TOTAL UNIDAD]] -> 0.28951089 | R16: =LISTPROD3[[#This Row],[% GANANCIA]]*LISTPROD3[[#This Row],[COSTO TOTAL UNIDAD]] -> 1683.8413 | S16: =+LISTPROD3[[#This Row],[PRECIO DE VENTA 1]]-LISTPROD3[[#This Row],[PRECIO VENTA POR RECETA]] -> -2256.1897 | T16: 0 | V16: =+LISTPROD3[[#This Row],[% GANANCIA2]]*LISTPROD3[[#This Row],[COSTO TOTAL UNIDAD]] -> 0 | W16: =LISTPROD3[[#This Row],[PRECIO DE VENTA2]]-LISTPROD3[[#This Row],[PRECIO VENTA POR RECETA]] -> -9756.1897 | AC16: 7500 | AD16: 0 | AE16: 0 | AF16: 0 | AH16: OK
A17: CM01 | B17: CARDO MARIANO (Capsulas) | C17: ENVASE TIENE 60 CAPSULAS | D17: HOMEOPATICOS | E17: CAPSULAS | F17: CAPSULAS 60 UND | I17: ANGIE-LHC | J17: ='RECETAS CAPS'!U19 -> 3943.7 | K17: ='Gtos Varios'!$B$22 -> 3070.5429 | L17: =+LISTPROD3[[#This Row],[TOTAL GASTOS VARIOS]]+LISTPROD3[[#This Row],[PRECIO DE PRODUCCIÓN POR UND]] -> 7014.2429 | M17: ='RECETAS CAPS'!U25 -> 3351.3172 | N17: ='RECETAS CAPS'!V25 -> 0.44 | O17: ='RECETAS CAPS'!U26 -> 10967.947 | P17: 10968 | Q17: =(LISTPROD3[[#This Row],[PRECIO DE VENTA 1]]-LISTPROD3[[#This Row],[COSTO TOTAL UNIDAD]])/LISTPROD3[[#This Row],[COSTO TOTAL UNIDAD]] -> 0.56367554 | R17: =LISTPROD3[[#This Row],[% GANANCIA]]*LISTPROD3[[#This Row],[COSTO TOTAL UNIDAD]] -> 3953.7571 | AC17: 9600 | AD17: 0 | AE17: 0 | AF17: 0 | AH17: OK
A18: CT01 | B18: CARTILAGO DE TIBURON | C18: 500 ML-Jarabe | D18: HOMEOPATICOS | E18: JARABES | F18: 500 ML | G18: PHARMA | I18: LUIS-FARMACIA NATIVA | J18: ='RECETAS JARABES'!G327 -> 2482.1171 | K18: ='Gtos Varios'!$B$22 -> 3070.5429 | L18: =+LISTPROD3[[#This Row],[PRECIO DE PRODUCCIÓN POR UND]]+LISTPROD3[[#This Row],[TOTAL GASTOS VARIOS]] -> 5552.6599 | M18: ='RECETAS JARABES'!$G$332 -> 3323.7254 | N18: ='RECETAS JARABES'!$H$332 -> 0.54 | O18: ='RECETAS JARABES'!$G$333 -> 9478.7725 | P18: 6000 | Q18: =(LISTPROD3[[#This Row],[PRECIO DE VENTA 1]]-LISTPROD3[[#This Row],[COSTO TOTAL UNIDAD]])/LISTPROD3[[#This Row],[COSTO TOTAL UNIDAD]] -> 0.080563205 | R18: =LISTPROD3[[#This Row],[% GANANCIA]]*LISTPROD3[[#This Row],[COSTO TOTAL UNIDAD]] -> 447.34008 | S18: =+LISTPROD3[[#This Row],[PRECIO DE VENTA 1]]-LISTPROD3[[#This Row],[PRECIO VENTA POR RECETA]] -> -3478.7725 | T18: 5000 | U18: =(LISTPROD3[[#This Row],[PRECIO DE VENTA2]]-LISTPROD3[[#This Row],[COSTO TOTAL UNIDAD]])/LISTPROD3[[#This Row],[COSTO TOTAL UNIDAD]] -> -0.099530663 | V18: =+LISTPROD3[[#This Row],[% GANANCIA2]]*LISTPROD3[[#This Row],[COSTO TOTAL UNIDAD]] -> -552.65992 | W18: =LISTPROD3[[#This Row],[PRECIO DE VENTA2]]-LISTPROD3[[#This Row],[PRECIO VENTA POR RECETA]] -> -4478.7725 | X18: 5000 | Y18: =(LISTPROD3[[#This Row],[PRECIO DE VENTA 3]]-LISTPROD3[[#This Row],[COSTO TOTAL UNIDAD]])/LISTPROD3[[#This Row],[COSTO TOTAL UNIDAD]] -> -0.099530663 | Z18: =LISTPROD3[[#This Row],[% GANANCIA3]]*LISTPROD3[[#This Row],[COSTO TOTAL UNIDAD]] -> -552.65992 | AC18: 6000 | AD18: 5000 | AE18: 5000 | AF18: 5000 | AH18: OK
A19: CHP01 | B19: CHANCA PIEDRA JARABE | C19: 500 ML-Jarabe | D19: HOMEOPATICOS | E19: JARABES | F19: 500 ML | G19: PHARMA | I19: LUIS-FARMACIA NATIVA | J19: ='RECETAS JARABES'!G364 -> 2112.0478 | K19: ='Gtos Varios'!$B$22 -> 3070.5429 | L19: =+LISTPROD3[[#This Row],[PRECIO DE PRODUCCIÓN POR UND]]+LISTPROD3[[#This Row],[TOTAL GASTOS VARIOS]] -> 5182.5907 | M19: ='RECETAS JARABES'!$G$369 -> 3355.2871 | N19: ='RECETAS JARABES'!H369 -> 0.58 | O19: ='RECETAS JARABES'!G370 -> 9140.265 | P19: 6000 | Q19: =(LISTPROD3[[#This Row],[PRECIO DE VENTA 1]]-LISTPROD3[[#This Row],[COSTO TOTAL UNIDAD]])/LISTPROD3[[#This Row],[COSTO TOTAL UNIDAD]] -> 0.15772215 | R19: =LISTPROD3[[#This Row],[% GANANCIA]]*LISTPROD3[[#This Row],[COSTO TOTAL UNIDAD]] -> 817.40932 | S19: =+LISTPROD3[[#This Row],[PRECIO DE VENTA 1]]-LISTPROD3[[#This Row],[PRECIO VENTA POR RECETA]] -> -3140.265 | T19: 5000 | U19: =(LISTPROD3[[#This Row],[PRECIO DE VENTA2]]-LISTPROD3[[#This Row],[COSTO TOTAL UNIDAD]])/LISTPROD3[[#This Row],[COSTO TOTAL UNIDAD]] -> -0.035231546 | V19: =+LISTPROD3[[#This Row],[% GANANCIA2]]*LISTPROD3[[#This Row],[COSTO TOTAL UNIDAD]] -> -182.59068 | W19: =LISTPROD3[[#This Row],[PRECIO DE VENTA2]]-LISTPROD3[[#This Row],[PRECIO VENTA POR RECETA]] -> -4140.265 | X19: 5000 | Y19: =(LISTPROD3[[#This Row],[PRECIO DE VENTA 3]]-LISTPROD3[[#This Row],[COSTO TOTAL UNIDAD]])/LISTPROD3[[#This Row],[COSTO TOTAL UNIDAD]] -> -0.035231546 | Z19: =LISTPROD3[[#This Row],[% GANANCIA3]]*LISTPROD3[[#This Row],[COSTO TOTAL UNIDAD]] -> -182.59068 | AC19: 6000 | AD19: 5000 | AE19: 5000 | AF19: 5000 | AH19: OK
A20: CL01 | B20: CIR LAN LITRO | C20: 1000 ML-Jarabe | D20: HOMEOPATICOS | E20: JARABES | F20: LITRO 1000 ML | G20: NATURAL PALAGAR | I20: MARIA-IMPERIO NATURAL | J20: ='RECETAS JARABES'!G396 -> 1054.3662 | K20: ='Gtos Varios'!$B$22 -> 3070.5429 | L20: =+LISTPROD3[[#This Row],[PRECIO DE PRODUCCIÓN POR UND]]+LISTPROD3[[#This Row],[TOTAL GASTOS VARIOS]] -> 4124.9091 | M20: ='RECETAS JARABES'!G401 -> 3450.9262 | N20: ='RECETAS JARABES'!H401 -> 0.73 | O20: ='RECETAS JARABES'!G402 -> 8178.2224 | P20: 7000 | Q20: =(LISTPROD3[[#This Row],[PRECIO DE VENTA 1]]-LISTPROD3[[#This Row],[COSTO TOTAL UNIDAD]])/LISTPROD3[[#This Row],[COSTO TOTAL UNIDAD]] -> 0.69700711 | R20: =LISTPROD3[[#This Row],[% GANANCIA]]*LISTPROD3[[#This Row],[COSTO TOTAL UNIDAD]] -> 2875.0909 | S20: =+LISTPROD3[[#This Row],[PRECIO DE VENTA 1]]-LISTPROD3[[#This Row],[PRECIO VENTA POR RECETA]] -> -1178.2224 | AC20: 7000 | AD20: 0 | AE20: 0 | AF20: 0 | AH20: OK
A21: CV01 | B21: CIRCULAV LITRO | C21: 1000 ML-Jarabe | D21: HOMEOPATICOS | E21: JARABES | F21: LITRO 1000 ML | G21: CUBANO | I21: ANGIE-LHC | J21: ='RECETAS JARABES'!G426 -> 2060.4127 | K21: ='Gtos Varios'!$B$22 -> 3070.5429 | L21: =+LISTPROD3[[#This Row],[PRECIO DE PRODUCCIÓN POR UND]]+LISTPROD3[[#This Row],[TOTAL GASTOS VARIOS]] -> 5130.9555 | M21: ='RECETAS JARABES'!G431 -> 3210.6719 | N21: ='RECETAS JARABES'!H431 -> 0.56 | O21: ='RECETAS JARABES'!G432 -> 8944.0146 | P21: 7500 | Q21: =(LISTPROD3[[#This Row],[PRECIO DE VENTA 1]]-LISTPROD3[[#This Row],[COSTO TOTAL UNIDAD]])/LISTPROD3[[#This Row],[COSTO TOTAL UNIDAD]] -> 0.46171604 | R21: =LISTPROD3[[#This Row],[% GANANCIA]]*LISTPROD3[[#This Row],[COSTO TOTAL UNIDAD]] -> 2369.0445 | S21: =+LISTPROD3[[#This Row],[PRECIO DE VENTA 1]]-LISTPROD3[[#This Row],[PRECIO VENTA POR RECETA]] -> -1444.0146 | AC21: 7500 | AD21: 0 | AE21: 0 | AF21: 0 | AH21: PREGUNTAR A LUIS POR PRECIOS Y FORMULA
A22: CG01 | B22: COLAGENO | C22: 500 ML-Jarabe | D22: HOMEOPATICOS | E22: JARABES | F22: 500 ML | G22: PHARMA | I22: LUIS-FARMACIA NATIVA | J22: ='RECETAS JARABES'!G460 -> 2662.4346 | K22: ='Gtos Varios'!$B$22 -> 3070.5429 | L22: =+LISTPROD3[[#This Row],[PRECIO DE PRODUCCIÓN POR UND]]+LISTPROD3[[#This Row],[TOTAL GASTOS VARIOS]] -> 5732.9774 | M22: ='RECETAS JARABES'!G465 -> 3357.7432 | N22: ='RECETAS JARABES'!H465 -> 0.53 | O22: ='RECETAS JARABES'!G466 -> 9693.1078 | P22: 6000 | Q22: =(LISTPROD3[[#This Row],[PRECIO DE VENTA 1]]-LISTPROD3[[#This Row],[COSTO TOTAL UNIDAD]])/LISTPROD3[[#This Row],[COSTO TOTAL UNIDAD]] -> 0.046576599 | R22: =LISTPROD3[[#This Row],[% GANANCIA]]*LISTPROD3[[#This Row],[COSTO TOTAL UNIDAD]] -> 267.02259 | S22: =+LISTPROD3[[#This Row],[PRECIO DE VENTA 1]]-LISTPROD3[[#This Row],[PRECIO VENTA POR RECETA]] -> -3693.1078 | T22: 5000 | U22: =(LISTPROD3[[#This Row],[PRECIO DE VENTA2]]-LISTPROD3[[#This Row],[COSTO TOTAL UNIDAD]])/LISTPROD3[[#This Row],[COSTO TOTAL UNIDAD]] -> -0.12785283 | V22: =+LISTPROD3[[#This Row],[% GANANCIA2]]*LISTPROD3[[#This Row],[COSTO TOTAL UNIDAD]] -> -732.97741 | W22: =LISTPROD3[[#This Row],[PRECIO DE VENTA2]]-LISTPROD3[[#This Row],[PRECIO VENTA POR RECETA]] -> -4693.1078 | X22: 5000 | Y22: =(LISTPROD3[[#This Row],[PRECIO DE VENTA 3]]-LISTPROD3[[#This Row],[COSTO TOTAL UNIDAD]])/LISTPROD3[[#This Row],[COSTO TOTAL UNIDAD]] -> -0.12785283 | Z22: =LISTPROD3[[#This Row],[% GANANCIA3]]*LISTPROD3[[#This Row],[COSTO TOTAL UNIDAD]] -> -732.97741 | AC22: 6000 | AD22: 5000 | AE22: 5000 | AF22: 5000 | AH22: OK
A23: CC01 | B23: COLIRIO CUBANO (Gotas) | C23: 25 ML | D23: HOMEOPATICOS | E23: GOTAS | F23: 25 ML | I23: LUIS-FARMACIA NATIVA | J23: FALTA RECETA | K23: ='Gtos Varios'!$B$22 -> 3070.5429 | M23: ='RECETAS GOTAS'!K156 -> 3391.0937 | N23: ='RECETAS GOTAS'!L156 -> 0.62 | O23: ='RECETAS GOTAS'!K157 -> 8860.5996 | P23: 3500 | Q23: =(LISTPROD3[[#This Row],[PRECIO DE VENTA 1]]-LISTPROD3[[#This Row],[COSTO TOTAL UNIDAD]])/LISTPROD3[[#This Row],[COSTO TOTAL UNIDAD]] -> #DIV/0! | R23: =LISTPROD3[[#This Row],[% GANANCIA]]*LISTPROD3[[#This Row],[COSTO TOTAL UNIDAD]] -> #DIV/0! | T23: 0 | U23: =(LISTPROD3[[#This Row],[PRECIO DE VENTA2]]-LISTPROD3[[#This Row],[COSTO TOTAL UNIDAD]])/LISTPROD3[[#This Row],[COSTO TOTAL UNIDAD]] -> #DIV/0! | V23: =LISTPROD3[[#This Row],[PRECIO DE VENTA2]]*LISTPROD3[[#This Row],[% GANANCIA2]] -> #DIV/0! | W23: =LISTPROD3[[#This Row],[PRECIO DE VENTA2]]-LISTPROD3[[#This Row],[PRECIO VENTA POR RECETA]] -> -8860.5996 | X23: 0 | AC23: 3500 | AD23: 0 | AE23: 0 | AF23: 0 | AH23: PREGUNTAR A LUIS POR PRECIOS Y FORMULA
A24: CSZ01 | B24: COLIRIO SABILA Y ZANAHORIA (Gotas) | C24: 25 ML | D24: HOMEOPATICOS | E24: GOTAS | F24: 25 ML | I24: LUIS-FARMACIA NATIVA | J24: FALTA RECETA | K24: ='Gtos Varios'!$B$22 -> 3070.5429 | P24: 2000 | Q24: =(LISTPROD3[[#This Row],[PRECIO DE VENTA 1]]-LISTPROD3[[#This Row],[COSTO TOTAL UNIDAD]])/LISTPROD3[[#This Row],[COSTO TOTAL UNIDAD]] -> #DIV/0! | R24: =LISTPROD3[[#This Row],[% GANANCIA]]*LISTPROD3[[#This Row],[COSTO TOTAL UNIDAD]] -> #DIV/0! | T24: 5000 | U24: =(LISTPROD3[[#This Row],[PRECIO DE VENTA2]]-LISTPROD3[[#This Row],[COSTO TOTAL UNIDAD]])/LISTPROD3[[#This Row],[COSTO TOTAL UNIDAD]] -> #DIV/0! | V24: =LISTPROD3[[#This Row],[PRECIO DE VENTA2]]*LISTPROD3[[#This Row],[% GANANCIA2]] -> #DIV/0! | W24: =LISTPROD3[[#This Row],[PRECIO DE VENTA2]]-LISTPROD3[[#This Row],[PRECIO VENTA POR RECETA]] -> 5000 | X24: 5000 | AC24: 2000 | AD24: 5000 | AE24: 5000 | AF24: 5000 | AH24: FALTA
A25: CCN01 | B25: COLON CLEARSEN | C25: 500 ML-Jarabe | D25: HOMEOPATICOS | E25: JARABES | F25: 500 ML | G25: PHARMA | I25: LUIS-FARMACIA NATIVA | J25: FALTA PRECIO PROD | K25: ='Gtos Varios'!$B$22 -> 3070.5429 | L25: =+LISTPROD3[[#This Row],[PRECIO DE PRODUCCIÓN POR UND]]+LISTPROD3[[#This Row],[TOTAL GASTOS VARIOS]] -> #VALUE! | M25: ='RECETAS JARABES'!G500 -> 3378.6696 | N25: ='RECETAS JARABES'!H500 -> 0.58 | O25: ='RECETAS JARABES'!G501 -> 9203.9619 | P25: 6000 | R25: =LISTPROD3[[#This Row],[% GANANCIA]]*LISTPROD3[[#This Row],[COSTO TOTAL UNIDAD]] -> #VALUE! | S25: =+LISTPROD3[[#This Row],[PRECIO DE VENTA 1]]-LISTPROD3[[#This Row],[PRECIO VENTA POR RECETA]] -> -3203.9619 | T25: 5000 | U25: =(LISTPROD3[[#This Row],[PRECIO DE VENTA2]]-LISTPROD3[[#This Row],[COSTO TOTAL UNIDAD]])/LISTPROD3[[#This Row],[COSTO TOTAL UNIDAD]] -> #VALUE! | V25: =+LISTPROD3[[#This Row],[% GANANCIA2]]*LISTPROD3[[#This Row],[COSTO TOTAL UNIDAD]] -> #VALUE! | W25: =LISTPROD3[[#This Row],[PRECIO DE VENTA2]]-LISTPROD3[[#This Row],[PRECIO VENTA POR RECETA]] -> -4203.9619 | X25: 5000 | Y25: =(LISTPROD3[[#This Row],[PRECIO DE VENTA 3]]-LISTPROD3[[#This Row],[COSTO TOTAL UNIDAD]])/LISTPROD3[[#This Row],[COSTO TOTAL UNIDAD]] -> #VALUE! | Z25: =LISTPROD3[[#This Row],[% GANANCIA3]]*LISTPROD3[[#This Row],[COSTO TOTAL UNIDAD]] -> #VALUE! | AC25: 6000 | AD25: 5000 | AE25: 5000 | AF25: 5000 | AH25: OK
A26: CB01 | B26: COMPLEJO B | C26: 500 ML-Jarabe | D26: HOMEOPATICOS | E26: JARABES | F26: 500 ML | G26: PHARMA | I26: LUIS-FARMACIA NATIVA | J26: ='RECETAS JARABES'!G529 -> 2179.2612 | K26: ='Gtos Varios'!$B$22 -> 3070.5429 | L26: =+LISTPROD3[[#This Row],[PRECIO DE PRODUCCIÓN POR UND]]+LISTPROD3[[#This Row],[TOTAL GASTOS VARIOS]] -> 5249.804 | M26: ='RECETAS JARABES'!$G$534 -> 3394.2709 | N26: ='RECETAS JARABES'!$H$534 -> 0.58 | O26: ='RECETAS JARABES'!$G$535 -> 9246.4621 | P26: 6000 | Q26: =(LISTPROD3[[#This Row],[PRECIO DE VENTA 1]]-LISTPROD3[[#This Row],[COSTO TOTAL UNIDAD]])/LISTPROD3[[#This Row],[COSTO TOTAL UNIDAD]] -> 0.1428998 | R26: =LISTPROD3[[#This Row],[% GANANCIA]]*LISTPROD3[[#This Row],[COSTO TOTAL UNIDAD]] -> 750.19596 | S26: =+LISTPROD3[[#This Row],[PRECIO DE VENTA 1]]-LISTPROD3[[#This Row],[PRECIO VENTA POR RECETA]] -> -3246.4621 | T26: 5000 | U26: =(LISTPROD3[[#This Row],[PRECIO DE VENTA2]]-LISTPROD3[[#This Row],[COSTO TOTAL UNIDAD]])/LISTPROD3[[#This Row],[COSTO TOTAL UNIDAD]] -> -0.047583498 | V26: =+LISTPROD3[[#This Row],[% GANANCIA2]]*LISTPROD3[[#This Row],[COSTO TOTAL UNIDAD]] -> -249.80404 | W26: =LISTPROD3[[#This Row],[PRECIO DE VENTA2]]-LISTPROD3[[#This Row],[PRECIO VENTA POR RECETA]] -> -4246.4621 | X26: 5000 | Y26: =(LISTPROD3[[#This Row],[PRECIO DE VENTA 3]]-LISTPROD3[[#This Row],[COSTO TOTAL UNIDAD]])/LISTPROD3[[#This Row],[COSTO TOTAL UNIDAD]] -> -0.047583498 | Z26: =LISTPROD3[[#This Row],[% GANANCIA3]]*LISTPROD3[[#This Row],[COSTO TOTAL UNIDAD]] -> -249.80404 | AC26: 6000 | AD26: 5000 | AE26: 5000 | AF26: 5000 | AH26: OK
A27: CPC01 | B27: CONCENTRADO DE PLANTAS CUBANA | C27: 500 ML-Jarabe | D27: HOMEOPATICOS | E27: JARABES | F27: 500 ML | G27: CUBANO | H27: TIENE CAMARA DE COMERCIO UN TERCERO COMO DISTRIBUIDOR | I27: ANGIE-LHC | J27: ='RECETAS JARABES'!G562 -> 2122.6344 | K27: ='Gtos Varios'!$B$22 -> 3070.5429 | L27: =+LISTPROD3[[#This Row],[PRECIO DE PRODUCCIÓN POR UND]]+LISTPROD3[[#This Row],[TOTAL GASTOS VARIOS]] -> 5193.1773 | M27: ='RECETAS JARABES'!$G$567 -> 3303.4717 | N27: ='RECETAS JARABES'!$H$567 -> 0.57 | O27: ='RECETAS JARABES'!$G$568 -> 9099.0361 | P27: 6000 | Q27: =(LISTPROD3[[#This Row],[PRECIO DE VENTA 1]]-LISTPROD3[[#This Row],[COSTO TOTAL UNIDAD]])/LISTPROD3[[#This Row],[COSTO TOTAL UNIDAD]] -> 0.15536206 | R27: =LISTPROD3[[#This Row],[% GANANCIA]]*LISTPROD3[[#This Row],[COSTO TOTAL UNIDAD]] -> 806.82273 | S27: =+LISTPROD3[[#This Row],[PRECIO DE VENTA 1]]-LISTPROD3[[#This Row],[PRECIO VENTA POR RECETA]] -> -3099.0361 | T27: 5000 | U27: =(LISTPROD3[[#This Row],[PRECIO DE VENTA2]]-LISTPROD3[[#This Row],[COSTO TOTAL UNIDAD]])/LISTPROD3[[#This Row],[COSTO TOTAL UNIDAD]] -> -0.037198281 | V27: =+LISTPROD3[[#This Row],[% GANANCIA2]]*LISTPROD3[[#This Row],[COSTO TOTAL UNIDAD]] -> -193.17727 | W27: =LISTPROD3[[#This Row],[PRECIO DE VENTA2]]-LISTPROD3[[#This Row],[PRECIO VENTA POR RECETA]] -> -4099.0361 | X27: 5000 | Y27: =(LISTPROD3[[#This Row],[PRECIO DE VENTA 3]]-LISTPROD3[[#This Row],[COSTO TOTAL UNIDAD]])/LISTPROD3[[#This Row],[COSTO TOTAL UNIDAD]] -> -0.037198281 | Z27: =LISTPROD3[[#This Row],[% GANANCIA3]]*LISTPROD3[[#This Row],[COSTO TOTAL UNIDAD]] -> -193.17727 | AC27: 6000 | AD27: 5000 | AE27: 5000 | AF27: 5000 | AH27: PREGUNTAR A LUIS POR PRECIOS Y FORMULA
A28: CI01 | B28: COPA DE INDIO | C28: 500 ML-Jarabe | D28: HOMEOPATICOS | E28: JARABES | F28: 500 ML | G28: PHARMA | I28: LUIS-FARMACIA NATIVA | J28: ='RECETAS JARABES'!G595 -> 2072.6344 | K28: ='Gtos Varios'!$B$22 -> 3070.5429 | L28: =+LISTPROD3[[#This Row],[PRECIO DE PRODUCCIÓN POR UND]]+LISTPROD3[[#This Row],[TOTAL GASTOS VARIOS]] -> 5143.1773 | M28: ='RECETAS JARABES'!G600 -> 3389.883 | N28: ='RECETAS JARABES'!H600 -> 0.59 | O28: ='RECETAS JARABES'!G601 -> 9135.4474 | P28: 6000 | Q28: =(LISTPROD3[[#This Row],[PRECIO DE VENTA 1]]-LISTPROD3[[#This Row],[COSTO TOTAL UNIDAD]])/LISTPROD3[[#This Row],[COSTO TOTAL UNIDAD]] -> 0.16659405 | R28: =LISTPROD3[[#This Row],[% GANANCIA]]*LISTPROD3[[#This Row],[COSTO TOTAL UNIDAD]] -> 856.82273 | S28: =+LISTPROD3[[#This Row],[PRECIO DE VENTA 1]]-LISTPROD3[[#This Row],[PRECIO VENTA POR RECETA]] -> -3135.4474 | T28: 5000 | U28: =(LISTPROD3[[#This Row],[PRECIO DE VENTA2]]-LISTPROD3[[#This Row],[COSTO TOTAL UNIDAD]])/LISTPROD3[[#This Row],[COSTO TOTAL UNIDAD]] -> -0.027838292 | V28: =+LISTPROD3[[#This Row],[% GANANCIA2]]*LISTPROD3[[#This Row],[COSTO TOTAL UNIDAD]] -> -143.17727 | W28: =LISTPROD3[[#This Row],[PRECIO DE VENTA2]]-LISTPROD3[[#This Row],[PRECIO VENTA POR RECETA]] -> -4135.4474 | X28: 5000 | Y28: =(LISTPROD3[[#This Row],[PRECIO DE VENTA 3]]-LISTPROD3[[#This Row],[COSTO TOTAL UNIDAD]])/LISTPROD3[[#This Row],[COSTO TOTAL UNIDAD]] -> -0.027838292 | Z28: =LISTPROD3[[#This Row],[% GANANCIA3]]*LISTPROD3[[#This Row],[COSTO TOTAL UNIDAD]] -> -143.17727 | AC28: 6000 | AD28: 5000 | AE28: 5000 | AF28: 5000 | AH28: OK
A29: DZ01 | B29: DIABETIZAN | C29: 500 ML-Jarabe | D29: HOMEOPATICOS | E29: JARABES | F29: 500 ML | G29: PHARMA | I29: LUIS-FARMACIA NATIVA | J29: FALTA PRECIO PROD | K29: ='Gtos Varios'!$B$22 -> 3070.5429 | L29: =+LISTPROD3[[#This Row],[PRECIO DE PRODUCCIÓN POR UND]]+LISTPROD3[[#This Row],[TOTAL GASTOS VARIOS]] -> #VALUE! | M29: ='RECETAS JARABES'!G634 -> 3357.1036 | N29: ='RECETAS JARABES'!H634 -> 0.58 | O29: ='RECETAS JARABES'!G635 -> 9145.2133 | P29: 6000 | Q29: =(LISTPROD3[[#This Row],[PRECIO DE VENTA 1]]-LISTPROD3[[#This Row],[COSTO TOTAL UNIDAD]])/LISTPROD3[[#This Row],[COSTO TOTAL UNIDAD]] -> #VALUE! | R29: =LISTPROD3[[#This Row],[% GANANCIA]]*LISTPROD3[[#This Row],[COSTO TOTAL UNIDAD]] -> #VALUE! | S29: =+LISTPROD3[[#This Row],[PRECIO DE VENTA 1]]-LISTPROD3[[#This Row],[PRECIO VENTA POR RECETA]] -> -3145.2133 | T29: 5000 | U29: =(LISTPROD3[[#This Row],[PRECIO DE VENTA2]]-LISTPROD3[[#This Row],[COSTO TOTAL UNIDAD]])/LISTPROD3[[#This Row],[COSTO TOTAL UNIDAD]] -> #VALUE! | V29: =+LISTPROD3[[#This Row],[% GANANCIA2]]*LISTPROD3[[#This Row],[COSTO TOTAL UNIDAD]] -> #VALUE! | W29: =LISTPROD3[[#This Row],[PRECIO DE VENTA2]]-LISTPROD3[[#This Row],[PRECIO VENTA POR RECETA]] -> -4145.2133 | X29: 5000 | Y29: =(LISTPROD3[[#This Row],[PRECIO DE VENTA 3]]-LISTPROD3[[#This Row],[COSTO TOTAL UNIDAD]])/LISTPROD3[[#This Row],[COSTO TOTAL UNIDAD]] -> #VALUE! | Z29: =LISTPROD3[[#This Row],[% GANANCIA3]]*LISTPROD3[[#This Row],[COSTO TOTAL UNIDAD]] -> #VALUE! | AC29: 6000 | AD29: 5000 | AE29: 5000 | AF29: 5000 | AH29: OK
A30: du01 | B30: DOLORAN ULTRA (lleva Spray) | C30: PASTILLAS 60 | D30: HOMEOPATICOS | E30: PASTILLAS | F30: PASTILLAS DE 60 UND | I30: LUIS-FARMACIA NATIVA | J30: ='RECETAS PASTILLAS'!R16 -> 4900 | K30: ='Gtos Varios'!$B$22 -> 3070.5429 | L30: =+LISTPROD3[[#This Row],[TOTAL GASTOS VARIOS]]+LISTPROD3[[#This Row],[PRECIO DE PRODUCCIÓN POR UND]] -> 7970.5429 | M30: ='RECETAS PASTILLAS'!R48 -> 3257.7134 | N30: ='RECETAS PASTILLAS'!S48 -> 0.38 | O30: ='RECETAS PASTILLAS'!R49 -> 11830.643 | P30: 10500 | Q30: =(LISTPROD3[[#This Row],[PRECIO DE VENTA 1]]-LISTPROD3[[#This Row],[COSTO TOTAL UNIDAD]])/LISTPROD3[[#This Row],[COSTO TOTAL UNIDAD]] -> 0.31735067 | R30: =LISTPROD3[[#This Row],[% GANANCIA]]*LISTPROD3[[#This Row],[COSTO TOTAL UNIDAD]] -> 2529.4571 | AB30: Se toma solo el costo de produccion no margen de utilidad | AC30: 10500 | AD30: 0 | AE30: 0 | AF30: 0 | AH30: FALTA
A31: E01 | B31: ELIXIR (Gotas) | C31: 25 ML | D31: HOMEOPATICOS | E31: GOTAS | F31: 25 ML | I31: LUIS-FARMACIA NATIVA | J31: ='RECETAS GOTAS'!K92 -> 2006 | K31: ='Gtos Varios'!$B$22 -> 3070.5429 | L31: =+LISTPROD3[[#This Row],[TOTAL GASTOS VARIOS]]+LISTPROD3[[#This Row],[PRECIO DE PRODUCCIÓN POR UND]] -> 5076.5429 | M31: ='RECETAS GOTAS'!K97 -> 3350.5687 | N31: ='RECETAS GOTAS'!L97 -> 0.59 | O31: ='RECETAS GOTAS'!K98 -> 9029.4987 | P31: 600 | Q31: =(LISTPROD3[[#This Row],[PRECIO DE VENTA 1]]-LISTPROD3[[#This Row],[COSTO TOTAL UNIDAD]])/LISTPROD3[[#This Row],[COSTO TOTAL UNIDAD]] -> -0.88180933 | R31: =LISTPROD3[[#This Row],[% GANANCIA]]*LISTPROD3[[#This Row],[COSTO TOTAL UNIDAD]] -> -4476.5429 | T31: 0 | U31: =(LISTPROD3[[#This Row],[PRECIO DE VENTA2]]-LISTPROD3[[#This Row],[COSTO TOTAL UNIDAD]])/LISTPROD3[[#This Row],[COSTO TOTAL UNIDAD]] -> -1 | V31: =LISTPROD3[[#This Row],[PRECIO DE VENTA2]]*LISTPROD3[[#This Row],[% GANANCIA2]] -> 0 | W31: =LISTPROD3[[#This Row],[PRECIO DE VENTA2]]-LISTPROD3[[#This Row],[PRECIO VENTA POR RECETA]] -> -9029.4987 | X31: 0 | AC31: 600 | AD31: 0 | AE31: 0 | AF31: 0 | AH31: FALTA
A32: EDM01 | B32: ENFERMEDADES DE LA MUJER | C32: 500 ML-Jarabe | D32: HOMEOPATICOS | E32: JARABES | F32: 500 ML | G32: PHARMA | I32: LUIS-FARMACIA NATIVA | J32: FALTA PRECIO PROD | K32: ='Gtos Varios'!$B$22 -> 3070.5429 | L32: =+LISTPROD3[[#This Row],[PRECIO DE PRODUCCIÓN POR UND]]+LISTPROD3[[#This Row],[TOTAL GASTOS VARIOS]] -> #VALUE! | M32: ='RECETAS JARABES'!G669 -> 3364.3853 | N32: ='RECETAS JARABES'!H669 -> 0.58 | O32: ='RECETAS JARABES'!G670 -> 9165.0497 | P32: 6000 | Q32: =(LISTPROD3[[#This Row],[PRECIO DE VENTA 1]]-LISTPROD3[[#This Row],[COSTO TOTAL UNIDAD]])/LISTPROD3[[#This Row],[COSTO TOTAL UNIDAD]] -> #VALUE! | R32: =LISTPROD3[[#This Row],[% GANANCIA]]*LISTPROD3[[#This Row],[COSTO TOTAL UNIDAD]] -> #VALUE! | S32: =+LISTPROD3[[#This Row],[PRECIO DE VENTA 1]]-LISTPROD3[[#This Row],[PRECIO VENTA POR RECETA]] -> -3165.0497 | T32: 5000 | U32: =(LISTPROD3[[#This Row],[PRECIO DE VENTA2]]-LISTPROD3[[#This Row],[COSTO TOTAL UNIDAD]])/LISTPROD3[[#This Row],[COSTO TOTAL UNIDAD]] -> #VALUE! | V32: =+LISTPROD3[[#This Row],[% GANANCIA2]]*LISTPROD3[[#This Row],[COSTO TOTAL UNIDAD]] -> #VALUE! | W32: =LISTPROD3[[#This Row],[PRECIO DE VENTA2]]-LISTPROD3[[#This Row],[PRECIO VENTA POR RECETA]] -> -4165.0497 | X32: 5000 | Y32: =(LISTPROD3[[#This Row],[PRECIO DE VENTA 3]]-LISTPROD3[[#This Row],[COSTO TOTAL UNIDAD]])/LISTPROD3[[#This Row],[COSTO TOTAL UNIDAD]] -> #VALUE! | Z32: =LISTPROD3[[#This Row],[% GANANCIA3]]*LISTPROD3[[#This Row],[COSTO TOTAL UNIDAD]] -> #VALUE! | AC32: 6000 | AD32: 5000 | AE32: 5000 | AF32: 5000 | AH32: OK
A33: EMX01 | B33: ERECMAX | C33: 500 ML-Jarabe | D33: HOMEOPATICOS | E33: JARABES | F33: 500 ML | G33: PHARMA | I33: LUIS-FARMACIA NATIVA | J33: ='RECETAS JARABES'!G699 -> 3065.3275 | K33: ='Gtos Varios'!$B$22 -> 3070.5429 | L33: =+LISTPROD3[[#This Row],[PRECIO DE PRODUCCIÓN POR UND]]+LISTPROD3[[#This Row],[TOTAL GASTOS VARIOS]] -> 6135.8704 | M33: ='RECETAS JARABES'!G704 -> 3006.5765 | N33: ='RECETAS JARABES'!H704 -> 0.49 | O33: ='RECETAS JARABES'!G705 -> 9142.4469 | P33: 6000 | Q33: =(LISTPROD3[[#This Row],[PRECIO DE VENTA 1]]-LISTPROD3[[#This Row],[COSTO TOTAL UNIDAD]])/LISTPROD3[[#This Row],[COSTO TOTAL UNIDAD]] -> -0.02214362 | R33: =LISTPROD3[[#This Row],[% GANANCIA]]*LISTPROD3[[#This Row],[COSTO TOTAL UNIDAD]] -> -135.87038 | S33: =+LISTPROD3[[#This Row],[PRECIO DE VENTA 1]]-LISTPROD3[[#This Row],[PRECIO VENTA POR RECETA]] -> -3142.4469 | T33: 5000 | U33: =(LISTPROD3[[#This Row],[PRECIO DE VENTA2]]-LISTPROD3[[#This Row],[COSTO TOTAL UNIDAD]])/LISTPROD3[[#This Row],[COSTO TOTAL UNIDAD]] -> -0.18511968 | V33: =+LISTPROD3[[#This Row],[% GANANCIA2]]*LISTPROD3[[#This Row],[COSTO TOTAL UNIDAD]] -> -1135.8704 | W33: =LISTPROD3[[#This Row],[PRECIO DE VENTA2]]-LISTPROD3[[#This Row],[PRECIO VENTA POR RECETA]] -> -4142.4469 | X33: 5000 | Y33: =(LISTPROD3[[#This Row],[PRECIO DE VENTA 3]]-LISTPROD3[[#This Row],[COSTO TOTAL UNIDAD]])/LISTPROD3[[#This Row],[COSTO TOTAL UNIDAD]] -> -0.18511968 | Z33: =LISTPROD3[[#This Row],[% GANANCIA3]]*LISTPROD3[[#This Row],[COSTO TOTAL UNIDAD]] -> -1135.8704 | AC33: 6000 | AD33: 5000 | AE33: 5000 | AF33: 5000 | AH33: OK
A34: FO01 | B34: FENOGRECO (Capsulas) | C34: ENVASE TIENE 60 CAPSULAS | D34: HOMEOPATICOS | E34: CAPSULAS | F34: CAPSULAS 60 UND | I34: ANGIE-LHC | J34: ='RECETAS CAPS'!AI19 -> 2926.25 | K34: ='Gtos Varios'!$B$22 -> 3070.5429 | L34: =+LISTPROD3[[#This Row],[TOTAL GASTOS VARIOS]]+LISTPROD3[[#This Row],[PRECIO DE PRODUCCIÓN POR UND]] -> 5996.7929 | M34: ='RECETAS CAPS'!AI25 -> 3365.5818 | N34: ='RECETAS CAPS'!AJ25 -> 0.51 | O34: ='RECETAS CAPS'!AI26 -> 9964.7618 | P34: 8700 | Q34: =(LISTPROD3[[#This Row],[PRECIO DE VENTA 1]]-LISTPROD3[[#This Row],[COSTO TOTAL UNIDAD]])/LISTPROD3[[#This Row],[COSTO TOTAL UNIDAD]] -> 0.45077547 | R34: =LISTPROD3[[#This Row],[% GANANCIA]]*LISTPROD3[[#This Row],[COSTO TOTAL UNIDAD]] -> 2703.2071 | AC34: 8700 | AD34: 0 | AE34: 0 | AF34: 0 | AH34: OK
A35: FT01 | B35: FERROVIT LT | C35: 1000 ML-Jarabe | D35: HOMEOPATICOS | E35: JARABES | F35: LITRO 1000 ML | G35: CUBANO | I35: ANGIE-LHC | J35: ='RECETAS JARABES'!G730 -> 2202.7729 | K35: ='Gtos Varios'!$B$22 -> 3070.5429 | L35: =+LISTPROD3[[#This Row],[PRECIO DE PRODUCCIÓN POR UND]]+LISTPROD3[[#This Row],[TOTAL GASTOS VARIOS]] -> 5273.3158 | M35: ='RECETAS JARABES'!G735 -> 3005.79 | N35: ='RECETAS JARABES'!H735 -> 0.57 | O35: ='RECETAS JARABES'!G736 -> 8279.1058 | P35: 7500 | Q35: =(LISTPROD3[[#This Row],[PRECIO DE VENTA 1]]-LISTPROD3[[#This Row],[COSTO TOTAL UNIDAD]])/LISTPROD3[[#This Row],[COSTO TOTAL UNIDAD]] -> 0.42225505 | R35: =LISTPROD3[[#This Row],[% GANANCIA]]*LISTPROD3[[#This Row],[COSTO TOTAL UNIDAD]] -> 2226.6842 | S35: =+LISTPROD3[[#This Row],[PRECIO DE VENTA 1]]-LISTPROD3[[#This Row],[PRECIO VENTA POR RECETA]] -> -779.1058 | T35: 5000 | U35: =(LISTPROD3[[#This Row],[PRECIO DE VENTA2]]-LISTPROD3[[#This Row],[COSTO TOTAL UNIDAD]])/LISTPROD3[[#This Row],[COSTO TOTAL UNIDAD]] -> -0.05182997 | V35: =+LISTPROD3[[#This Row],[% GANANCIA2]]*LISTPROD3[[#This Row],[COSTO TOTAL UNIDAD]] -> -273.3158 | W35: =LISTPROD3[[#This Row],[PRECIO DE VENTA2]]-LISTPROD3[[#This Row],[PRECIO VENTA POR RECETA]] -> -3279.1058 | X35: 2000 | Y35: =(LISTPROD3[[#This Row],[PRECIO DE VENTA 3]]-LISTPROD3[[#This Row],[COSTO TOTAL UNIDAD]])/LISTPROD3[[#This Row],[COSTO TOTAL UNIDAD]] -> -0.62073199 | Z35: =LISTPROD3[[#This Row],[% GANANCIA3]]*LISTPROD3[[#This Row],[COSTO TOTAL UNIDAD]] -> -3273.3158 | AC35: 7500 | AD35: 5000 | AE35: 2000 | AF35: 2000 | AH35: OK
A36: FM01 | B36: FERRUM LITRO | C36: 1000 ML-Jarabe | D36: HOMEOPATICOS | E36: JARABES | F36: LITRO 1000 ML | G36: CUBANO | I36: ANGIE-LHC | J36: ='RECETAS JARABES'!G761 -> 2202.7729 | K36: ='Gtos Varios'!$B$22 -> 3070.5429 | L36: =+LISTPROD3[[#This Row],[PRECIO DE PRODUCCIÓN POR UND]]+LISTPROD3[[#This Row],[TOTAL GASTOS VARIOS]] -> 5273.3158 | M36: ='RECETAS JARABES'!G766 -> 3005.79 | N36: ='RECETAS JARABES'!H766 -> 0.57 | O36: ='RECETAS JARABES'!G767 -> 8279.1058 | P36: 7500 | Q36: =(LISTPROD3[[#This Row],[PRECIO DE VENTA 1]]-LISTPROD3[[#This Row],[COSTO TOTAL UNIDAD]])/LISTPROD3[[#This Row],[COSTO TOTAL UNIDAD]] -> 0.42225505 | R36: =LISTPROD3[[#This Row],[% GANANCIA]]*LISTPROD3[[#This Row],[COSTO TOTAL UNIDAD]] -> 2226.6842 | S36: =+LISTPROD3[[#This Row],[PRECIO DE VENTA 1]]-LISTPROD3[[#This Row],[PRECIO VENTA POR RECETA]] -> -779.1058 | AC36: 7500 | AD36: 0 | AE36: 0 | AF36: 0 | AH36: PREGUNTAR A LUIS POR PRECIOS Y FORMULA
A37: FL01 | B37: FLEXDOL | C37: PASTILLAS 40 | D37: HOMEOPATICOS | E37: PASTILLAS | F37: PASTILLAS DE 40 UND | I37: LUIS-FARMACIA NATIVA | J37: ='RECETAS PASTILLAS'!G45 -> 4670 | K37: ='Gtos Varios'!$B$22 -> 3070.5429 | L37: =+LISTPROD3[[#This Row],[TOTAL GASTOS VARIOS]]+LISTPROD3[[#This Row],[PRECIO DE PRODUCCIÓN POR UND]] -> 7740.5429 | M37: ='RECETAS PASTILLAS'!G50 -> 3253.7427 | N37: ='RECETAS PASTILLAS'!H50 -> 0.39 | O37: ='RECETAS PASTILLAS'!G51 -> 11596.673 | P37: 7000 | Q37: =(LISTPROD3[[#This Row],[PRECIO DE VENTA 1]]-LISTPROD3[[#This Row],[COSTO TOTAL UNIDAD]])/LISTPROD3[[#This Row],[COSTO TOTAL UNIDAD]] -> -0.095670662 | R37: =LISTPROD3[[#This Row],[% GANANCIA]]*LISTPROD3[[#This Row],[COSTO TOTAL UNIDAD]] -> -740.54286 | T37: 7000 | U37: =(LISTPROD3[[#This Row],[PRECIO DE VENTA2]]-LISTPROD3[[#This Row],[COSTO TOTAL UNIDAD]])/LISTPROD3[[#This Row],[COSTO TOTAL UNIDAD]] -> -0.095670662 | V37: =LISTPROD3[[#This Row],[PRECIO DE VENTA2]]*LISTPROD3[[#This Row],[% GANANCIA2]] -> -669.69463 | X37: 7000 | Y37: =(LISTPROD3[[#This Row],[PRECIO DE VENTA 3]]-LISTPROD3[[#This Row],[COSTO TOTAL UNIDAD]])/LISTPROD3[[#This Row],[COSTO TOTAL UNIDAD]] -> -0.095670662 | Z37: =+LISTPROD3[[#This Row],[PRECIO DE VENTA 3]]*LISTPROD3[[#This Row],[% GANANCIA3]] -> -669.69463 | AB37: Se toma solo el costo de produccion no margen de utilidad | AC37: 7000 | AD37: 7000 | AE37: 7000 | AF37: 7000 | AH37: OK
A38: FC01 | B38: FLOR DE CENTELLA | C38: 500 ML-Jarabe | D38: HOMEOPATICOS | E38: JARABES | F38: 500 ML | G38: SALUD Y BELLEZA NATUTAL | I38: LUIS-FARMACIA NATIVA | J38: ='RECETAS JARABES'!G794 -> 2122.6344 | K38: ='Gtos Varios'!$B$22 -> 3070.5429 | L38: =+LISTPROD3[[#This Row],[PRECIO DE PRODUCCIÓN POR UND]]+LISTPROD3[[#This Row],[TOTAL GASTOS VARIOS]] -> 5193.1773 | M38: ='RECETAS JARABES'!G799 -> 2960.111 | N38: ='RECETAS JARABES'!H799 -> 0.57 | O38: ='RECETAS JARABES'!G800 -> 8153.2883 | P38: 7000 | Q38: =(LISTPROD3[[#This Row],[PRECIO DE VENTA 1]]-LISTPROD3[[#This Row],[COSTO TOTAL UNIDAD]])/LISTPROD3[[#This Row],[COSTO TOTAL UNIDAD]] -> 0.34792241 | R38: =LISTPROD3[[#This Row],[% GANANCIA]]*LISTPROD3[[#This Row],[COSTO TOTAL UNIDAD]] -> 1806.8227 | S38: =+LISTPROD3[[#This Row],[PRECIO DE VENTA 1]]-LISTPROD3[[#This Row],[PRECIO VENTA POR RECETA]] -> -1153.2883 | AC38: 7000 | AD38: 0 | AE38: 0 | AF38: 0 | AH38: OK
A39: FCN01 | B39: FLOR DE CENTELLA NUEVA | C39: 500 ML-Jarabe | D39: HOMEOPATICOS | E39: JARABES | F39: 500 ML | G39: SALUD Y BELLEZA NATUTAL | I39: LUIS-FARMACIA NATIVA | J39: ='RECETAS JARABES'!G826 -> 2016.5143 | K39: ='Gtos Varios'!$B$22 -> 3070.5429 | L39: =+LISTPROD3[[#This Row],[PRECIO DE PRODUCCIÓN POR UND]]+LISTPROD3[[#This Row],[TOTAL GASTOS VARIOS]] -> 5087.0572 | M39: ='RECETAS JARABES'!G831 -> 2899.6226 | N39: ='RECETAS JARABES'!H831 -> 0.57 | O39: ='RECETAS JARABES'!G832 -> 7986.6798 | P39: 7000 | Q39: =(LISTPROD3[[#This Row],[PRECIO DE VENTA 1]]-LISTPROD3[[#This Row],[COSTO TOTAL UNIDAD]])/LISTPROD3[[#This Row],[COSTO TOTAL UNIDAD]] -> 0.37604115 | R39: =LISTPROD3[[#This Row],[% GANANCIA]]*LISTPROD3[[#This Row],[COSTO TOTAL UNIDAD]] -> 1912.9428 | S39: =+LISTPROD3[[#This Row],[PRECIO DE VENTA 1]]-LISTPROD3[[#This Row],[PRECIO VENTA POR RECETA]] -> -986.67975 | AC39: 7000 | AD39: 0 | AE39: 0 | AF39: 0 | AH39: OK
A40: GT01 | B40: GASTRIUL | C40: 500 ML-Jarabe | D40: HOMEOPATICOS | E40: JARABES | F40: 500 ML | G40: PHARMA | I40: LUIS-FARMACIA NATIVA | J40: FALTA PRECIO PROD | K40: ='Gtos Varios'!$B$22 -> 3070.5429 | L40: =+LISTPROD3[[#This Row],[PRECIO DE PRODUCCIÓN POR UND]]+LISTPROD3[[#This Row],[TOTAL GASTOS VARIOS]] -> #VALUE! | M40: ='RECETAS JARABES'!$G$866 -> 3032.8279 | N40: ='RECETAS JARABES'!$H$866 -> 0.58 | O40: ='RECETAS JARABES'!$G$867 -> 8261.8415 | P40: 6000 | Q40: =(LISTPROD3[[#This Row],[PRECIO DE VENTA 1]]-LISTPROD3[[#This Row],[COSTO TOTAL UNIDAD]])/LISTPROD3[[#This Row],[COSTO TOTAL UNIDAD]] -> #VALUE! | R40: =LISTPROD3[[#This Row],[% GANANCIA]]*LISTPROD3[[#This Row],[COSTO TOTAL UNIDAD]] -> #VALUE! | S40: =+LISTPROD3[[#This Row],[PRECIO DE VENTA 1]]-LISTPROD3[[#This Row],[PRECIO VENTA POR RECETA]] -> -2261.8415 | T40: 6000 | U40: =(LISTPROD3[[#This Row],[PRECIO DE VENTA2]]-LISTPROD3[[#This Row],[COSTO TOTAL UNIDAD]])/LISTPROD3[[#This Row],[COSTO TOTAL UNIDAD]] -> #VALUE! | V40: =+LISTPROD3[[#This Row],[% GANANCIA2]]*LISTPROD3[[#This Row],[COSTO TOTAL UNIDAD]] -> #VALUE! | W40: =LISTPROD3[[#This Row],[PRECIO DE VENTA2]]-LISTPROD3[[#This Row],[PRECIO VENTA POR RECETA]] -> -2261.8415 | X40: 6000 | Y40: =(LISTPROD3[[#This Row],[PRECIO DE VENTA 3]]-LISTPROD3[[#This Row],[COSTO TOTAL UNIDAD]])/LISTPROD3[[#This Row],[COSTO TOTAL UNIDAD]] -> #VALUE! | Z40: =LISTPROD3[[#This Row],[% GANANCIA3]]*LISTPROD3[[#This Row],[COSTO TOTAL UNIDAD]] -> #VALUE! | AC40: 6000 | AD40: 6000 | AE40: 6000 | AF40: 6000 | AG40: Se ajusto precio el 17/03/2025 con Elaine | AH40: OK
...

Sheet Recetas x Prod
A1: NOTA:TODO LO QUE SEA LITRO SE MANEJA EL PROMEDIO DE LA PAPA
A8: CODIGO | B8: 7T01 | G8: CODIGO | H8: AM01 | L8: CODIGO | M8: CA01 | R8: CODIGO | S8: AV01 | V8: CODIGO | W8: DZ01 | Z8: CODIGO | AA8: GM01 | AD8: CODIGO | AE8: PS01 | AH8: CODIGO | AI8: VC01 | AL8: CODIGO | AR8: CODIGO | AT8: RE01 | AY8: CODIGO | BA8: SS01 | BE8: CODIGO | BG8: CA02
A9: PRODUCTO | B9: =VLOOKUP(B8,LISTPROD[],2,FALSE) -> 7 TOROS | G9: PRODUCTO | H9: =VLOOKUP(H8,LISTPROD[],2,FALSE) -> ALICITRIM LT | L9: PRODUCTO | M9: =VLOOKUP(M8,LISTPROD[],2,FALSE) -> CATUAMA (Capsulas) | R9: PRODUCTO | S9: =VLOOKUP(S8,LISTPROD[],2,FALSE) -> ARTERIO VENOSO | V9: PRODUCTO | W9: =VLOOKUP(W8,LISTPROD[],2,FALSE) -> DIABETIZAN | Z9: PRODUCTO | AA9: =VLOOKUP(AA8,LISTPROD[],2,FALSE) -> GREEN MARVIN (Ungüento) | AD9: PRODUCTO | AE9: =VLOOKUP(AE8,LISTPROD[],2,FALSE) -> PAPA SILVESTRE POLVO (500 gr) | AH9: PRODUCTO | AI9: =VLOOKUP(AI8,LISTPROD[],2,FALSE) -> VINO CEREBRAL | AL9: PRODUCTO | AM9: =VLOOKUP(AM8,LISTPROD[],2,FALSE) -> #N/A | AR9: PRODUCTO | AT9: =VLOOKUP(AT8,LISTPROD[],2,FALSE) -> RESCATE (Gotas) | AY9: PRODUCTO | BA9: =VLOOKUP(BA8,LISTPROD[],2,FALSE) -> STRESS (Gotas) | BE9: PRODUCTO | BG9: =VLOOKUP(BG8,LISTPROD[],2,FALSE) -> CALENDULA (Capsulas)
A10: ALMACEN | B10: =VLOOKUP(B8,LISTPROD[],3,FALSE) -> 7TRS | G10: ALMACEN | H10: =VLOOKUP(H8,LISTPROD[],3,FALSE) -> ALICITRIN CIRCULATORIO | L10: ALMACEN | M10: =VLOOKUP(M8,LISTPROD[],3,FALSE) -> CATUAMA | R10: ALMACEN | S10: =VLOOKUP(S8,LISTPROD[],3,FALSE) -> ARTERIO VENOSO | V10: ALMACEN | W10: =VLOOKUP(W8,LISTPROD[],3,FALSE) -> DIABETIZAN | Z10: ALMACEN | AA10: =VLOOKUP(AA8,LISTPROD[],3,FALSE) -> GREEN MARVIN (Ungüento) | AD10: ALMACEN | AE10: =VLOOKUP(AE8,LISTPROD[],3,FALSE) -> PAPA SILVESTRE POLVO (500 gr) | AH10: ALMACEN | AI10: =VLOOKUP(AI8,LISTPROD[],3,FALSE) -> VINO CEREBRAL | AL10: ALMACEN | AM10: =VLOOKUP(AM8,LISTPROD[],3,FALSE) -> #N/A | AR10: ALMACEN | AT10: =VLOOKUP(AT8,LISTPROD[],3,FALSE) -> RESCATE Gotas Orales | AY10: ALMACEN | BA10: =VLOOKUP(BA8,LISTPROD[],3,FALSE) -> STRESS Gotas Orales | BE10: ALMACEN | BG10: =VLOOKUP(BG8,LISTPROD[],3,FALSE) -> CALENDULA
A11: Total Cantidad Envasada | B11: 390 | G11: Total Cantidad Envasada | L11: Total Cantidad Envasada | R11: Total Cantidad Envasada | V11: Total Cantidad Envasada | Z11: Total Cantidad Envasada | AD11: Total Cantidad Envasada | AH11: Total Cantidad Envasada | AL11: Total Cantidad Envasada | AR11: Total Cantidad Envasada | AT11: 158 | AY11: Total Cantidad Envasada | BE11: Total Cantidad Envasada | BG11: 140
A12: Cantidad Unitaria | G12: Cantidad Unitaria | L12: Cantidad Unitaria | R12: Cantidad Unitaria | V12: Cantidad Unitaria | Z12: Cantidad Unitaria | AD12: Cantidad Unitaria | AH12: Cantidad Unitaria | AL12: Cantidad Unitaria | AR12: Cantidad Unitaria | AY12: Cantidad Unitaria | BE12: Cantidad Unitaria
A13: Presentación | B13: 500 ml | G13: Presentación | L13: Presentación | R13: Presentación | V13: Presentación | Z13: Presentación | AD13: Presentación | AH13: Presentación | AL13: Presentación | AR13: Presentación | AY13: Presentación | BE13: Presentación
A14: INGREDIENTES | B14: CANT | C14: GRAMOs/mL | G14: INGREDIENTES | H14: CANT | I14: GRAMOs/mL | L14: INGREDIENTES | M14: CANT | N14: GRAMOs/mL | R14: INGREDIENTES | S14: CANT | T14: GRAMOs/mL | V14: INGREDIENTES | W14: CANT | X14: GRAMOs/mL | Z14: INGREDIENTES | AA14: CANT | AB14: GRAMOs/mL | AD14: INGREDIENTES | AE14: CANT | AF14: GRAMOs/mL | AH14: INGREDIENTES | AI14: CANT | AJ14: GRAMOs/mL | AL14: INGREDIENTES | AM14: CANT | AN14: GRAMOs/mL | AR14: INGREDIENTES | AS14: CLASIFICACION | AT14: CANT | AU14: GRAMOs/mL | AV14: Cant x UNID | AY14: INGREDIENTES | AZ14: CLASIFICACION | BA14: CANT | BB14: GRAMOs/mL | BE14: INGREDIENTES | BF14: CLASIFICACION | BG14: CANT | BH14: GRAMOs/mL | BI14: Cant x UNID
A15: SULFATO FERROSO | B15: 1000 | C15: GR | G15: BENZODATO | H15: 600 | I15: GR | R15: BENZODATO | S15: 600 | V15: BENZODATO | W15: 600 | Z15: VASELINA | AA15: 5000 | AH15: BENZODATO | AI15: 600 | AR15: Dilución Floral de Impaciencia | AS15: INSUMO | AT15: ML | AU15: 1.5 | AV15: =AU15/$AT$11 -> 0.0094936709 | AY15: Dilución Floral de Oimo | AZ15: INSUMO | BA15: 1 | BB15: ML | BE15: PASTILLERO 180(38) PE BLANCO | BF15: EMPAQUE | BG15: UND | BH15: 140 | BI15: =BH15/$AT$192 -> 1
A16: BENZODATO | B16: 600 | C16: GR | G16: ACIDO CITRICO | H16: 500 | I16: GR | R16: CITRATO DE SODIO | S16: 200 | V16: CITRATO DE SODIO | W16: 200 | Z16: PARAFINA | AA16: 200 | AH16: CITRATO DE SODIO | AI16: 200 | AR16: Dilución Floral de Estrella de belén | AS16: INSUMO | AT16: ML | AU16: 1.5 | AV16: =AU16/$AT$11 -> 0.0094936709 | AY16: Dilución Floral de Estrella de belén | AZ16: INSUMO | BA16: 1 | BB16: ML | BE16: CALENDULA | BF16: INSUMO | BG16: GR | BH16: 4200 | BI16: =BH16/$AT$192 -> 30
A17: ACIDO CITRICO | B17: 300 | C17: GR | G17: CITRATO DE SODIO | H17: 200 | I17: GR | R17: ACIDO CITRICO | S17: 1000 | V17: ACIDO CITRICO | W17: 1000 | Z17: SALICILATO | AA17: 3000 | AH17: SABOR-NARANJA | AI17: 100 | AR17: Dilución Floral de Heliantemo | AS17: INSUMO | AT17: ML | AU17: 1.5 | AV17: =AU17/$AT$11 -> 0.0094936709 | AY17: Dilución Floral de Centaura | AZ17: INSUMO | BA17: 1 | BB17: ML | BE17: CAPSULAS | BF17: INSUMO | BG17: UND | BH17: 8400 | BI17: =BH17/$AT$192 -> 60
A18: COMPONENTE | B18: 150 | C18: GR | G18: GOMA XANTAN | H18: 900 | I18: GR | R18: GOMA XANTAN | S18: 800 | V18: ENDULZANTE | W18: 100 | Z18: MENTOL | AA18: 300 | AH18: SULFATO FERROSO | AI18: 1000 | AR18: Dilución Floral de Cerasifera | AS18: INSUMO | AT18: ML | AU18: 1.5 | AV18: =AU18/$AT$11 -> 0.0094936709 | AY18: Dilución Floral de Castaño blanco | AZ18: INSUMO | BA18: 1 | BB18: ML | BE18: TAPA 38 PD ENSAMBLADA PE VERDE | BF18: EMPAQUE | BG18: UND | BH18: 140 | BI18: =BH18/$AT$192 -> 1
A19: GOMA XANTAN | B19: 700 | C19: GR | G19: SABOR-NARANJA | H19: 100 | I19: GR | R19: SABOR-NARANJA | S19: 100 | V19: COLOR-PARDO | W19: 22 | Z19: COLOR-VERDE GRASA | AA19: 1 | AH19: GOMA XANTAN | AI19: 800 | AR19: Dilución Floral de Clemátide | AS19: INSUMO | AT19: ML | AU19: 1.5 | AV19: =AU19/$AT$11 -> 0.0094936709 | AY19: Dilución Floral de Ceratostigma | AZ19: INSUMO | BA19: 1 | BB19: ML | BE19: LINER DE TROQUEL 38 MM PS | BF19: EMPAQUE | BG19: UND | BH19: 140 | BI19: =BH19/$AT$192 -> 1
A20: COLOR-CARAMELO | B20: 100 | C20: GR | G20: COLOR-PARDO | H20: 20 | I20: GR | R20: SULFATO FERROSO | S20: 300 | V20: SABOR-MANGO | W20: 100 | AH20: ACIDO CITRICO | AI20: 300 | AR20: Alcohol al 96 % | AS20: INSUMO | AT20: ML | AU20: 600 | AV20: =AU20/$AT$11 -> 3.7974684 | AY20: Alcohol al 96 % | AZ20: INSUMO | BA20: 450 | BB20: ML | BE20: ETIQUETA | BF20: EMPAQUE | BG20: UND | BH20: 140 | BI20: =BH20/$AT$192 -> 1
A21: COLOR-PARDO | B21: 60 | C21: GR | G21: KIT DE PLANTAS | R21: COLOR-PARDO | S21: 60 | V21: KIT DE PLANTAS | AH21: COLOR-PARDO | AI21: 60 | AR21: Agua purificada | AS21: INSUMO | AT21: ML | AU21: 3100 | AV21: =AU21/$AT$11 -> 19.620253 | AY21: Agua purificada | AZ21: INSUMO | BA21: 2045 | BB21: ML | BE21: TERMOENCOGIBLE | BF21: EMPAQUE | BG21: UND | BH21: 140 | BI21: =BH21/$AT$192 -> 1
A22: CITRATO DE SODIO | B22: 200 | C22: GR | R22: KIT DE PLANTAS | AH22: ENDULZANTE | AI22: 100 | AR22: Frasco Ámbar 25 mL Boca 18 mm | AS22: EMPAQUE | AT22: UND | AU22: 158 | AY22: Frasco Ámbar 25 mL Boca 18 mm | AZ22: EMPAQUE | BB22: UND
A23: ENDULZANTE | B23: 200 | C23: GR | AH23: KIT DE PLANTAS | AR23: Perilla gotero Negra -Tapa negra con Pipeta dosificadora en vidrio . Boca 18 mm | AS23: EMPAQUE | AT23: UND | AU23: 158 | AY23: Perilla gotero Negra -Tapa negra con Pipeta dosificadora en vidrio . Boca 18 mm | AZ23: EMPAQUE | BB23: UND
A24: SABOR-FRESA | B24: 100 | C24: GR | AR24: Etiqueta | AS24: EMPAQUE | AT24: UND | AU24: 158 | AY24: Etiqueta | AZ24: EMPAQUE | BB24: UND
A25: KIT DE PLANTAS | AR25: Plegadiza | AS25: EMPAQUE | AT25: UND | AU25: 158 | AY25: Plegadiza | AZ25: EMPAQUE | BB25: UND
AR26: Banda de seguridad | AS26: EMPAQUE | AT26: UND | AU26: 158 | AY26: Banda de seguridad | AZ26: EMPAQUE | BB26: UND
A33: CODIGO | B33: AN01 | G33: CODIGO | H33: CO01 | L33: CODIGO | M33: PB01 | R33: CODIGO | S33: A01 | V33: CODIGO | W33: DU01 | Z33: CODIGO | AA33: IM01 | AD33: CODIGO | AE33: PF01 | AH33: CODIGO | AI33: VP01 | AL33: CODIGO | AR33: CODIGO | AT33: VS01 | AY33: CODIGO | BA33: AA01
A34: PRODUCTO | B34: =VLOOKUP(B33,LISTPROD[],2,FALSE) -> ARBRON | G34: PRODUCTO | H34: =VLOOKUP(H33,LISTPROD[],2,FALSE) -> CALCUBANO LT | L34: PRODUCTO | M34: =VLOOKUP(M33,LISTPROD[],2,FALSE) -> PROSTABELL | R34: PRODUCTO | S34: =VLOOKUP(S33,LISTPROD[],2,FALSE) -> ARTRIN | V34: PRODUCTO | W34: =VLOOKUP(W33,LISTPROD[],2,FALSE) -> DOLORAN ULTRA (pastillas) y Spray | Z34: PRODUCTO | AA34: =VLOOKUP(AA33,LISTPROD[],2,FALSE) -> INFAMOL-JARABE 500 ML | AD34: PRODUCTO | AE34: =VLOOKUP(AE33,LISTPROD[],2,FALSE) -> POTENFULL | AH34: PRODUCTO | AI34: =VLOOKUP(AI33,LISTPROD[],2,FALSE) -> VISION PLUS (Gotas) | AL34: PRODUCTO | AM34: =VLOOKUP(AM33,LISTPROD[],2,FALSE) -> #N/A | AR34: PRODUCTO | AT34: =VLOOKUP(AT33,LISTPROD[],2,FALSE) -> VICIOS (Gotas) | AY34: PRODUCTO | BA34: =VLOOKUP(BA33,LISTPROD[],2,FALSE) -> ALCACHOFA (Capsulas)
A35: ALMACEN | B35: =VLOOKUP(B33,LISTPROD[],3,FALSE) -> ARBRON | G35: ALMACEN | H35: =VLOOKUP(H33,LISTPROD[],3,FALSE) -> CALCUBANO | L35: ALMACEN | M35: =VLOOKUP(M33,LISTPROD[],3,FALSE) -> SAW PALMETTO-Esencia FLoral 500 ml | R35: ALMACEN | S35: =VLOOKUP(S33,LISTPROD[],3,FALSE) -> ARTRIN | V35: ALMACEN | W35: =VLOOKUP(W33,LISTPROD[],3,FALSE) -> DOLORAN ULTRA (pastillas) y Spray | Z35: ALMACEN | AA35: =VLOOKUP(AA33,LISTPROD[],3,FALSE) -> INFAMOL-JARABE 500 ML | AD35: ALMACEN | AE35: =VLOOKUP(AE33,LISTPROD[],3,FALSE) -> POTENFULL | AH35: ALMACEN | AI35: =VLOOKUP(AI33,LISTPROD[],3,FALSE) -> VISION PLUS (Gotas) | AL35: ALMACEN | AM35: =VLOOKUP(AM33,LISTPROD[],3,FALSE) -> #N/A | AR35: ALMACEN | AT35: =VLOOKUP(AT33,LISTPROD[],3,FALSE) -> VICIOS Gotas Orales | AY35: ALMACEN | BA35: =VLOOKUP(BA33,LISTPROD[],3,FALSE) -> ALCACHOFA
A36: Total Cantidad Envasada | G36: Total Cantidad Envasada | L36: Total Cantidad Envasada | R36: Total Cantidad Envasada | V36: Total Cantidad Envasada | Z36: Total Cantidad Envasada | AD36: Total Cantidad Envasada | AH36: Total Cantidad Envasada | AL36: Total Cantidad Envasada | AR36: Total Cantidad Envasada | AY36: Total Cantidad Envasada
A37: Cantidad Unitaria | G37: Cantidad Unitaria | L37: Cantidad Unitaria | R37: Cantidad Unitaria | V37: Cantidad Unitaria | Z37: Cantidad Unitaria | AD37: Cantidad Unitaria | AH37: Cantidad Unitaria | AL37: Cantidad Unitaria | AR37: Cantidad Unitaria | AY37: Cantidad Unitaria
A38: Presentación | G38: Presentación | L38: Presentación | R38: Presentación | V38: Presentación | Z38: Presentación | AD38: Presentación | AH38: Presentación | AL38: Presentación | AR38: Presentación | AY38: Presentación
A39: INGREDIENTES | B39: CANT | C39: GRAMOs/mL | G39: INGREDIENTES | H39: CANT | I39: GRAMOs/mL | L39: INGREDIENTES | M39: CANT | N39: GRAMOs/mL | R39: INGREDIENTES | S39: CANT | T39: GRAMOs/mL | V39: INGREDIENTES | W39: CANT | X39: GRAMOs/mL | Z39: INGREDIENTES | AA39: CANT | AB39: GRAMOs/mL | AD39: INGREDIENTES | AE39: CANT | AF39: GRAMOs/mL | AH39: INGREDIENTES | AI39: CANT | AJ39: GRAMOs/mL | AL39: INGREDIENTES | AM39: CANT | AN39: GRAMOs/mL | AR39: INGREDIENTES | AT39: CANT | AU39: GRAMOs/mL | AY39: INGREDIENTES | BA39: CANT | BB39: GRAMOs/mL
A40: BENZODATO | B40: 600 | G40: CLORURO DE MAGNESIO | H40: 7000 | L40: BENZODATO | M40: 600 | R40: PASTA BLANCA | S40: 1100 (TABLETA) | AD40: GOMA XANTAN | AE40: 700 | AH40: AGUA DESTILADA | AR40: Dilución Floral de Cerasifera | AT40: 1 | AU40: ML | AY40: Dilución Floral de Nogal | BA40: 1 | BB40: ML
A41: ACIDO CITRICO | B41: 600 | G41: CITATO DE SODIO | H41: 300 | L41: CITATO DE SODIO | M41: 200 | R41: CAJA ARTRIN | S41: 550 UND | AD41: BENZODATO | AE41: 600 | AH41: CLORURO DE SODIO | AI41: 150
A42: ENDULZANTE | B42: 50 | G42: BENZODATO | H42: 600 | L42: ACIDO CITRICO | M42: 1000 | AD42: ACIDO CITRICO | AE42: 1000 | AH42: CLOR-ROJO | AI42: 1
A43: CITRATO DE SODIO | B43: 200 | G43: SABOR-NARANJA | H43: 200 | L43: ENDULZANTE | M43: 150 | AD43: ENDULZANTE | AE43: 250
A44: SABOR DURAZNO | B44: 100 | G44: GOMA XANTAN | H44: 700 | L44: GOMA XANTAN | M44: 900 | AD44: SABOR-TROPICAL | AE44: 600
A45: COLOR-PARDO | B45: 20 | G45: COLOR-PARDO | H45: 40 | L45: COLOR-PARDO | M45: 20 | AD45: COMPONENTE T | AE45: 150
A46: GOMA XANTAN | B46: 800 | G46: KIT DE PLANTAS | L46: SABOR-NARNAJA | M46: 100 | AD46: EMULSION TROPICAL | AE46: 500
A47: KIT DE PLANTAS | L47: KIT DE PLANTAS | AD47: ENTURBIANTE | AE47: 500
AD48: KIT DE PLANTAS
A62: CODIGO | B62: BP01 | G62: CODIGO | H62: CM01 | L62: CODIGO | M62: PT01 | R62: CODIGO | S62: B01 | V62: CODIGO | W62: E01 | Z62: CODIGO | AD62: CODIGO | AE62: PG01 | AH62: CODIGO | AI62: VCF01 | AL62: CODIGO | AR62: CODIGO | AT62: GG01 | AY62: CODIGO | BA62: IN01
A63: PRODUCTO | B63: =VLOOKUP(B62,LISTPROD[],2,FALSE) -> BIL PRO | G63: PRODUCTO | H63: =VLOOKUP(H62,LISTPROD[],2,FALSE) -> CARDO MARIANO (Capsulas) | L63: PRODUCTO | M63: =VLOOKUP(M62,LISTPROD[],2,FALSE) -> PROX TAP LT | R63: PRODUCTO | S63: =VLOOKUP(S62,LISTPROD[],2,FALSE) -> BIO 44 | V63: PRODUCTO | W63: =VLOOKUP(W62,LISTPROD[],2,FALSE) -> ELIXIR (Gotas) | Z63: PRODUCTO | AA63: INFAMOL SPRAY | AD63: PRODUCTO | AE63: =VLOOKUP(AE62,LISTPROD[],2,FALSE) -> PPG | AH63: PRODUCTO | AI63: =VLOOKUP(AI62,LISTPROD[],2,FALSE) -> VITA CEREBRINA FRANCESA | AL63: PRODUCTO | AM63: =VLOOKUP(AM62,LISTPROD[],2,FALSE) -> #N/A | AR63: PRODUCTO | AT63: =VLOOKUP(AT62,LISTPROD[],2,FALSE) -> GINGOBILOBA (Capsulas) | AY63: PRODUCTO | BA63: =VLOOKUP(BA62,LISTPROD[],2,FALSE) -> INSOMNIO (Gotas)
A64: ALMACEN | B64: =VLOOKUP(B62,LISTPROD[],3,FALSE) -> BRIL-PRO | G64: ALMACEN | H64: =VLOOKUP(H62,LISTPROD[],3,FALSE) -> CARDO MARIANO (Capsulas) | L64: ALMACEN | M64: =VLOOKUP(M62,LISTPROD[],3,FALSE) -> PROX - TAP | R64: ALMACEN | S64: =VLOOKUP(S62,LISTPROD[],3,FALSE) -> BIO 44 | V64: ALMACEN | W64: =VLOOKUP(W62,LISTPROD[],3,FALSE) -> ELIXIR (Gotas) | Z64: ALMACEN | AA64: LUIS-FARMACIA NATIVA | AD64: ALMACEN | AE64: =VLOOKUP(AE62,LISTPROD[],3,FALSE) -> PPG | AH64: ALMACEN | AI64: =VLOOKUP(AI62,LISTPROD[],3,FALSE) -> VITA CEREBRINA FRANCESA | AL64: ALMACEN | AM64: =VLOOKUP(AM62,LISTPROD[],3,FALSE) -> #N/A | AR64: ALMACEN | AT64: =VLOOKUP(AT62,LISTPROD[],3,FALSE) -> GINKGO BILOBA | AY64: ALMACEN | BA64: =VLOOKUP(BA62,LISTPROD[],3,FALSE) -> INSOMNIO Gotas Orales
A65: Total Cantidad Envasada | G65: Total Cantidad Envasada | L65: Total Cantidad Envasada | R65: Total Cantidad Envasada | V65: Total Cantidad Envasada | Z65: Total Cantidad Envasada | AD65: Total Cantidad Envasada | AH65: Total Cantidad Envasada | AL65: Total Cantidad Envasada | AR65: Total Cantidad Envasada | AY65: Total Cantidad Envasada
...

Sheet RECETAS
A1: COMPRA | B1: GR | C1: KILO
A2: COMPRA | B2: ML | C2: LITROS
B4: OJO RECETA AJUSTADA PARA UNA SOLA UNIDAD
A9: NOMBRE | B9: potenfull | D9: NOMBRE | E9: emperador | G9: NOMBRE | H9: papa liquida | J9: NOMBRE | K9: wiltron | M9: NOMBRE | N9: enfermedades de la mujer
A10: INGREDIENTES | B10: GRAMOs/mL | D10: INGREDIENTES | E10: GRAMOs/mL | G10: INGREDIENTES | H10: GRAMOs/mL | J10: INGREDIENTES | K10: GRAMOs/mL | M10: INGREDIENTES | N10: GRAMOs/mL
A11: goma xanthan | B11: 700 | D11: goma xanthan | E11: 700 | G11: goma xanthan | H11: 700 | J11: goma xanthan | K11: 700 | M11: goma xanthan | N11: 900
A12: benzohato de sodio | B12: 600 | D12: benzohato de sodio | E12: 600 | G12: benzohato de sodio | H12: 600 | J12: benzohato de sodio | K12: 600 | M12: benzohato de sodio | N12: 600
A13: acido citrico | B13: 1000 | D13: acido citrico | E13: 1000 | G13: acido citrico | H13: 200 | J13: acido citrico | K13: 1000 | M13: acido citrico | N13: 300
A14: endulzante | B14: 250 | D14: endulzante | E14: 250 | G14: endulzante | H14: 200 | J14: sabor fresa | K14: 300 | M14: endulzante | N14: 150
A15: enturbiante | B15: 500 | D15: enturbiante | E15: 500 | G15: enturbiante | H15: 500 | J15: enturbiante | K15: 500 | M15: enturbiante | N15: 300
A16: sabor tropical | B16: 500 | D16: sabor tropical | E16: 500 | G16: sabor avena | H16: 100 | J16: sabor naranja | K16: 100 | M16: sabor frssa | N16: 100
A17: emulcion tropical | B17: 500 | D17: emulcion tropical | E17: 500 | G17: citrato de sodio | H17: 200 | J17: citrato de sodio | K17: 200 | M17: citrato de sodio | N17: 200
A18: componente T | B18: 150 | D18: componente T | E18: 150 | G18: plantas | H18: 1000 | J18: plantas | K18: 1000 | M18: plantas | N18: 1000
G19: color pardo | H19: 30 | J19: color pardo | K19: 60 | M19: color pardo | N19: 40
J20: sulfato ferroso | K20: 1000 | M20: color rojo | N20: 20
A21: NOMBRE | B21: limpiador arterio venoso | D21: NOMBRE | E21: factor d7 | G21: NOMBRE | H21: rompe quistes | J21: NOMBRE | K21: rompe quistes
A22: INGREDIENTES | B22: GRAMOs/mL | D22: INGREDIENTES | E22: GRAMOs/mL | G22: INGREDIENTES | H22: GRAMOs/mL | J22: INGREDIENTES | K22: GRAMOs/mL | M22: NOMBRE | N22: vitacerebrina
